<mujoco model="seobaike_finance_arm">
  <compiler angle="radian"/>

  <asset>
    <material name="steel" rgba="0.6 0.6 0.65 1"/>
    <material name="blue" rgba="0.1 0.3 0.8 1"/>
    <material name="red" rgba="0.8 0.1 0.1 1"/>
    <material name="green" rgba="0.1 0.7 0.2 1"/>
    <material name="gold" rgba="0.85 0.65 0.13 1"/>
    <material name="paper" rgba="0.95 0.95 0.9 1"/>
  </asset>

  <worldbody>
    <geom name="counter" size="1.5 1 0.02" pos="0 0 0.4" type="box" material="steel"/>
    <geom name="floor" size="3 3 0.1" type="plane" rgba="0.2 0.2 0.25 1"/>
    <geom name="scanner" size="0.15 0.1 0.03" pos="0.5 0 0.43" type="box" material="green"/>
    <geom name="cashbox" size="0.12 0.08 0.06" pos="0 -0.4 0.46" type="box" material="gold"/>
    <light pos="0 0 4" dir="0 0 -1" diffuse="0.9 0.9 0.9"/>
    <light pos="2 2 3" dir="-0.57735 -0.57735 -0.57735" diffuse="0.3 0.3 0.4"/>
    <body name="doc1" pos="-0.5 0 0.44">
      <joint type="free"/>
      <geom size="0.1 0.07 0.005" type="box" mass="0.05" material="paper"/>
    </body>
    <body name="doc2" pos="-0.5 0.02 0.45">
      <joint type="free"/>
      <geom size="0.1 0.07 0.005" type="box" mass="0.05" rgba="0.9 0.9 0.85 1"/>
    </body>
    <body name="base" pos="0 0.3 0.42">
      <geom size="0.08 0.03" type="cylinder" material="steel"/>
      <body name="turret" pos="0 0 0.06">
        <joint name="base_rotate" pos="0 0 0" axis="0 0 1" range="-3.14159 3.14159" damping="8"/>
        <geom size="0.06 0.04" type="cylinder" material="blue"/>
        <body name="upper_arm" pos="0 0 0.08">
          <joint name="shoulder" pos="0 0 0" axis="0 1 0" range="-1.5708 1.5708" damping="5"/>
          <geom size="0.035 0.18" type="capsule" material="blue"/>
          <body name="forearm" pos="0 0 0.36">
            <joint name="elbow" pos="0 0 0" axis="0 1 0" range="-2.26893 0" damping="4"/>
            <geom size="0.03 0.14" type="capsule" material="blue"/>
            <body name="wrist_body" pos="0 0 0.28">
              <joint name="wrist" pos="0 0 0" axis="1 0 0" range="-1.5708 1.5708" damping="2"/>
              <geom size="0.025 0.02" type="cylinder" material="steel"/>
              <body name="grip_l" pos="-0.03 0 0.04">
                <joint name="grip_left" pos="0 0 0" axis="1 0 0" type="slide" range="-0.01 0.03" damping="1"/>
                <geom size="0.008 0.015 0.03" type="box" material="red"/>
              </body>
              <body name="grip_r" pos="0.03 0 0.04">
                <joint name="grip_right" pos="0 0 0" axis="1 0 0" type="slide" range="-0.03 0.01" damping="1"/>
                <geom size="0.008 0.015 0.03" type="box" material="red"/>
              </body>
            </body>
          </body>
        </body>
      </body>
    </body>
  </worldbody>

  <actuator>
    <general joint="base_rotate" ctrlrange="-30 30"/>
    <general joint="shoulder" ctrlrange="-40 40"/>
    <general joint="elbow" ctrlrange="-40 40"/>
    <general joint="wrist" ctrlrange="-15 15"/>
    <general joint="grip_left" ctrlrange="-5 5"/>
    <general joint="grip_right" ctrlrange="-5 5"/>
  </actuator>
</mujoco>
